<?xml version="1.0" ?>
<!--Autogenerated by "taco/models/sdf2urdf" converter from "../kuka_iiwa/kuka_iiwa.sdf"-->
<robot name="kuka_iiwa">

    <link name="ground">
        <inertial>
            <origin xyz="0 0 0" rpy="0 0 0"/>
            <mass value="0.0001"/>
            <inertia ixx="0.000001"  ixy="0"  ixz="0" iyy="0.000001" iyz="0.0" izz="0.000001" />
        </inertial>
    </link>

    <link name="virtual1">
        <inertial>
            <origin xyz="0 0 0" rpy="0 0 0"/>
            <mass value="0.0001"/>
            <inertia ixx="0.000001"  ixy="0"  ixz="0" iyy="0.000001" iyz="0.0" izz="0.000001" />
        </inertial>
    </link>

    <link name="virtual2">
        <inertial>
            <origin xyz="0 0 0" rpy="0 0 0"/>
            <mass value="0.0001"/>
            <inertia ixx="0.000001"  ixy="0"  ixz="0" iyy="0.000001" iyz="0.0" izz="0.000001" />
        </inertial>
    </link>


    <link name="base_link">
        <inertial>
            <origin xyz="-0.1 0 0.07" rpy="0 0 0"/>
            <!--<origin xyz="0.0 0 0.07" rpy="0 0 0"/>-->
            <mass value="5"/>
            <inertia ixx="0.05"  ixy="0"  ixz="0" iyy="0.06" iyz="0" izz="0.03" />
        </inertial>
    <visual>
        <!--<origin xyz="0 0.20 -0.125" rpy="0 -0 0" />-->
        <origin xyz="0 0.0 -0.125" rpy="0 -0 0" />
        <geometry>
            <box size="0.4 0.7 0.25"/>
        </geometry>
    </visual>
    <visual>
        <origin xyz="-0.1 -0.2 0.3" rpy="0 -1.047197 0" />
        <geometry>
            <mesh filename="../../../robot_models/iiwa7/meshes/base.obj" scale="1 1 1" />
        </geometry>
    </visual>
    <visual>
        <origin xyz="0.1 -0.2 0.3" rpy="0 -1.047197 3.141592" />
        <geometry>
            <mesh filename="../../../robot_models/iiwa7/meshes/base.obj" scale="1 1 1" />
        </geometry>
    </visual>    
        <!-- <collision>
            <origin xyz="0 0 0" rpy="0 -0 0" />
            <geometry>
                <mesh filename="../../../robot_models/iiwa7/meshes/base.obj" scale="1 1 1" />
            </geometry>
        </collision> -->
    </link>


<!-- ARM 1-->

    <link name="link1">
      <inertial>
        <origin xyz="0 -0.03 0.12" rpy="0 0 0"/>
        <!--<origin xyz="0 -0.23 0.12" rpy="0 0 0"/>-->
        <mass value="3.4525"/>
        <inertia ixx="0.02183"  ixy="0"  ixz="0" iyy="0.007703" iyz="-0.003887" izz="0.02083" />
      </inertial>
        <visual>
            <origin xyz="0 0 0.005767" rpy="0 -0 0" />
            <geometry>
                <mesh filename="../../../robot_models/iiwa7/meshes/link0.obj" scale="1 1 1" />
            </geometry>
        </visual>
        <!-- <collision>
            <origin xyz="0 0 0" rpy="0 -0 0" />
            <geometry>
                <mesh filename="../../../robot_models/iiwa7/meshes/link0.obj" scale="1 1 1" />
            </geometry>
        </collision> -->
    </link>
    <link name="link2">
      <inertial>
        <origin xyz="-0.0003 0.042 0.059" rpy="0 0 0"/>
        <mass value="3.4821"/>
        <inertia ixx="0.02076"  ixz="0"  ixy="0.003626" izz="0.02179" iyz="0" iyy="0.00779" />
      </inertial>
        <visual>
            <origin xyz="0 0 -0.001733" rpy="0 -0 0" />
            <geometry>
                <mesh filename="../../../robot_models/iiwa7/meshes/link1.obj" scale="1 1 1" />
            </geometry>
        </visual>
        <!-- <collision>
            <origin xyz="0 0 0" rpy="0 -0 0" />
            <geometry>
                <mesh filename="../../../robot_models/iiwa7/meshes/link1.obj" scale="1 1 1" />
            </geometry>
        </collision> -->
    </link>
    <link name="link3">
      <inertial>
        <origin xyz="0 0.03 0.13" rpy="0 0 0"/>
        <mass value="4.05623"/>
        <inertia ixx="0.03204"  ixy="0"  ixz="0" iyy="0.00972" iyz="0.006227" izz="0.03042" />
      </inertial>
        <visual>
            <origin xyz="0 0 -0.026733" rpy="0 -0 0" />
            <geometry>
                <mesh filename="../../../robot_models/iiwa7/meshes/link2.obj" scale="1 1 1" />
            </geometry>
        </visual>
<!--         <collision>
            <origin xyz="0 0 0" rpy="0 -0 0" />
            <geometry>
                <mesh filename="../../../robot_models/iiwa7/meshes/link2.obj" scale="1 1 1" />
            </geometry>
        </collision> -->
    </link>
    <link name="link4">
      <inertial>
        <origin xyz="0 0.034 0.067" rpy="0 0 0"/>
        <mass value="3.4822"/>
        <inertia ixx="0.02178"  ixz="0"  ixy="0" izz="0.02075" iyz="-0.003625" iyy="0.007785" />
      </inertial>
        <visual>
            <origin xyz="0 0 0.000267" rpy="0 0 3.1415926535897" />
            <geometry>
                <mesh filename="../../../robot_models/iiwa7/meshes/link3.obj" scale="1 1 1" />
            </geometry>
        </visual>
        <!-- <collision>
            <origin xyz="0 0 0" rpy="0 -0 0" />
            <geometry>
                <mesh filename="../../../robot_models/iiwa7/meshes/link3.obj" scale="1 1 1" />
            </geometry>
        </collision> -->
    </link>
    <link name="link5">
      <inertial>
        <origin xyz="-0.0001 0.-021 0.076" rpy="0 0 0"/>
        <mass value="2.1633"/>
        <inertia ixx="0.01287"  ixy="0"  ixz="0" iyy="0.005708" iyz="0.003946" izz="0.21112" />
      </inertial>
        <visual>
            <origin xyz="0 0 -0.0237330" rpy="0 0 0" />
            <geometry>
                <mesh filename="../../../robot_models/iiwa7/meshes/link4.obj" scale="1 1 1" />
            </geometry>
        </visual>
        <!-- <collision>
            <origin xyz="0 0 0" rpy="0 -0 0" />
            <geometry>
                <mesh filename="../../../robot_models/iiwa7/meshes/link4.obj" scale="1 1 1" />
            </geometry>
        </collision> -->
    </link>
    <link name="link6">
      <inertial>
        <origin xyz="0 0.0004 0.0006" rpy="0 0 0"/>
        <mass value="2.3466"/>
        <inertia ixx="0.006509"  ixz="0"  ixy="0" izz="0.006259" iyz="0.00031891" iyy="0.204527" />
      </inertial>
        <visual>
            <origin xyz="0 0 0.0003267" rpy="0 0 0" />
            <geometry>
                <mesh filename="../../../robot_models/iiwa7/meshes/link5.obj" scale="1 1 1" />
            </geometry>
        </visual>
        <!-- <collision>
            <origin xyz="0 -0.06 0" rpy="0 -0 0" />
            <geometry>
                <mesh filename="../../../robot_models/iiwa7/meshes/link5.obj" scale="1 1 1" />
            </geometry>
        </collision> -->
    </link>
    <link name="link7">
      <inertial>
        <!-- <origin xyz="0 0 0.02" rpy="0 0 0"/> -->
        <!-- <mass value="3.129"/> -->
        <origin xyz="0 0 0.025" rpy="0 0 0"/>
        <mass value="3.529"/>
        <inertia ixx="0.01464"  ixy="0.0005912"  ixz="0" iyy="0.01465" iyz="0" izz="0.152872" />
      </inertial>
<!--       <inertial>
        <origin xyz="0 0 0" rpy="0 0 0"/>
        <mass value="0.0"/>
        <inertia ixx="0"  ixy="0"  ixz="0" iyy="0" iyz="0" izz="0.5" />
      </inertial> -->
        <visual>
            <origin xyz="0 0 0.0003267" rpy="0 0 0" />
            <geometry>
                <mesh filename="../../../robot_models/iiwa7/meshes/link6.obj" scale="1 1 1" />
            </geometry>
        </visual>
<!--         <collision>
            <origin xyz="0 0 0" rpy="0 0 0" />
            <geometry>
                <mesh filename="../../../robot_models/iiwa7/meshes/link6.obj" scale="1 1 1" />
            </geometry>
        </collision> -->
<!--         <visual>
            <origin xyz="0 0 0.08" rpy="0 0 0" />
            <geometry>
                <box size="0.08 0.08 0.08" />
            </geometry>
        </visual> -->
<!--         <collision>
            <origin xyz="0 0 0.08" rpy="0 0 0" />
            <geometry>
                <box size="0.08 0.08 0.08" />
            </geometry>
        </collision> -->
    </link>

    <link name="gripper1">
      <inertial>
        <origin xyz="0 0 0" rpy="0 0 0"/>
        <mass value="0.2"/>
        <inertia ixx="0.0001"  ixy="0"  ixz="0" iyy="0.0001" iyz="0" izz="0.0001" />
      </inertial>
        <visual>
            <origin xyz="0 0.01 0" rpy="0 0 0" />
            <geometry>
                <box size="0.03 0.01 0.07"/>
            </geometry>
                <material name="material_green">
                    <color rgba="0.1 0.6 0.1 1"/>
                </material>
        </visual>
        <collision>
            <origin xyz="0 0.01 0" rpy="0 0 0" />
            <geometry>
                <box size="0.03 0.01 0.07"/>
            </geometry>
        </collision>
    </link>

    <link name="gripper2">
      <inertial>
        <origin xyz="0 0 0" rpy="0 0 0"/>
        <mass value="0.2"/>
        <inertia ixx="0.0001"  ixy="0"  ixz="0" iyy="0.0001" iyz="0" izz="0.0001" />
      </inertial>
        <visual>
            <origin xyz="0 0.01 0" rpy="0 0 0" />
            <geometry>
                <box size="0.03 0.01 0.07"/>
            </geometry>
                <material name="material_green">
                    <color rgba="0.1 0.6 0.1 1"/>
                </material>
        </visual>

        <collision>
            <origin xyz="0 0.01 0" rpy="0 0 0" />
            <geometry>
                <box size="0.03 0.01 0.07"/>
            </geometry>
        </collision>
    </link>

    <!-- ARM 2 -->

    <link name="arm2_link1">
      <inertial>
        <origin xyz="0 -0.03 0.12" rpy="0 0 0"/>
        <!--<origin xyz="0 -0.23 0.12" rpy="0 0 0"/>-->
        <mass value="3.4525"/>
        <inertia ixx="0.02183"  ixy="0"  ixz="0" iyy="0.007703" iyz="-0.003887" izz="0.02083" />
      </inertial>
        <visual>
            <origin xyz="0 0 0.005767" rpy="0 -0 0" />
            <geometry>
                <mesh filename="../../../robot_models/iiwa7/meshes/link0.obj" scale="1 1 1" />
            </geometry>
        </visual>
        <!-- <collision>
            <origin xyz="0 0 0" rpy="0 -0 0" />
            <geometry>
                <mesh filename="../../../robot_models/iiwa7/meshes/link0.obj" scale="1 1 1" />
            </geometry>
        </collision> -->
    </link>
    <link name="arm2_link2">
      <inertial>
        <origin xyz="-0.0003 0.042 0.059" rpy="0 0 0"/>
        <mass value="3.4821"/>
        <inertia ixx="0.02076"  ixz="0"  ixy="0.003626" izz="0.02179" iyz="0" iyy="0.00779" />
      </inertial>
        <visual>
            <origin xyz="0 0 -0.001733" rpy="0 -0 0" />
            <geometry>
                <mesh filename="../../../robot_models/iiwa7/meshes/link1.obj" scale="1 1 1" />
            </geometry>
        </visual>
        <!-- <collision>
            <origin xyz="0 0 0" rpy="0 -0 0" />
            <geometry>
                <mesh filename="../../../robot_models/iiwa7/meshes/link1.obj" scale="1 1 1" />
            </geometry>
        </collision> -->
    </link>
    <link name="arm2_link3">
      <inertial>
        <origin xyz="0 0.03 0.13" rpy="0 0 0"/>
        <mass value="4.05623"/>
        <inertia ixx="0.03204"  ixy="0"  ixz="0" iyy="0.00972" iyz="0.006227" izz="0.03042" />
      </inertial>
        <visual>
            <origin xyz="0 0 -0.026733" rpy="0 -0 0" />
            <geometry>
                <mesh filename="../../../robot_models/iiwa7/meshes/link2.obj" scale="1 1 1" />
            </geometry>
        </visual>
<!--         <collision>
            <origin xyz="0 0 0" rpy="0 -0 0" />
            <geometry>
                <mesh filename="../../../robot_models/iiwa7/meshes/link2.obj" scale="1 1 1" />
            </geometry>
        </collision> -->
    </link>
    <link name="arm2_link4">
      <inertial>
        <origin xyz="0 0.034 0.067" rpy="0 0 0"/>
        <mass value="3.4822"/>
        <inertia ixx="0.02178"  ixz="0"  ixy="0" izz="0.02075" iyz="-0.003625" iyy="0.007785" />
      </inertial>
        <visual>
            <origin xyz="0 0 0.000267" rpy="0 0 3.1415926535897" />
            <geometry>
                <mesh filename="../../../robot_models/iiwa7/meshes/link3.obj" scale="1 1 1" />
            </geometry>
        </visual>
        <!-- <collision>
            <origin xyz="0 0 0" rpy="0 -0 0" />
            <geometry>
                <mesh filename="../../../robot_models/iiwa7/meshes/link3.obj" scale="1 1 1" />
            </geometry>
        </collision> -->
    </link>
    <link name="arm2_link5">
      <inertial>
        <origin xyz="-0.0001 0.-021 0.076" rpy="0 0 0"/>
        <mass value="2.1633"/>
        <inertia ixx="0.01287"  ixy="0"  ixz="0" iyy="0.005708" iyz="0.003946" izz="0.21112" />
      </inertial>
        <visual>
            <origin xyz="0 0 -0.0237330" rpy="0 0 0" />
            <geometry>
                <mesh filename="../../../robot_models/iiwa7/meshes/link4.obj" scale="1 1 1" />
            </geometry>
        </visual>
        <!-- <collision>
            <origin xyz="0 0 0" rpy="0 -0 0" />
            <geometry>
                <mesh filename="../../../robot_models/iiwa7/meshes/link4.obj" scale="1 1 1" />
            </geometry>
        </collision> -->
    </link>
    <link name="arm2_link6">
      <inertial>
        <origin xyz="0 0.0004 0.0006" rpy="0 0 0"/>
        <mass value="2.3466"/>
        <inertia ixx="0.006509"  ixz="0"  ixy="0" izz="0.006259" iyz="0.00031891" iyy="0.204527" />
      </inertial>
        <visual>
            <origin xyz="0 0 0.0003267" rpy="0 0 0" />
            <geometry>
                <mesh filename="../../../robot_models/iiwa7/meshes/link5.obj" scale="1 1 1" />
            </geometry>
        </visual>
        <!-- <collision>
            <origin xyz="0 -0.06 0" rpy="0 -0 0" />
            <geometry>
                <mesh filename="../../../robot_models/iiwa7/meshes/link5.obj" scale="1 1 1" />
            </geometry>
        </collision> -->
    </link>
    <link name="arm2_link7">
      <inertial>
        <!-- <origin xyz="0 0 0.02" rpy="0 0 0"/> -->
        <!-- <mass value="3.129"/> -->
        <origin xyz="0 0 0.025" rpy="0 0 0"/>
        <mass value="3.529"/>
        <inertia ixx="0.01464"  ixy="0.0005912"  ixz="0" iyy="0.01465" iyz="0" izz="0.152872" />
      </inertial>
<!--       <inertial>
        <origin xyz="0 0 0" rpy="0 0 0"/>
        <mass value="0.0"/>
        <inertia ixx="0"  ixy="0"  ixz="0" iyy="0" iyz="0" izz="0.5" />
      </inertial> -->
        <visual>
            <origin xyz="0 0 0.0003267" rpy="0 0 0" />
            <geometry>
                <mesh filename="../../../robot_models/iiwa7/meshes/link6.obj" scale="1 1 1" />
            </geometry>
        </visual>
<!--         <collision>
            <origin xyz="0 0 0" rpy="0 0 0" />
            <geometry>
                <mesh filename="../../../robot_models/iiwa7/meshes/link6.obj" scale="1 1 1" />
            </geometry>
        </collision> -->
<!--         <visual>
            <origin xyz="0 0 0.08" rpy="0 0 0" />
            <geometry>
                <box size="0.08 0.08 0.08" />
            </geometry>
        </visual> -->
<!--         <collision>
            <origin xyz="0 0 0.08" rpy="0 0 0" />
            <geometry>
                <box size="0.08 0.08 0.08" />
            </geometry>
        </collision> -->
    </link>

    <link name="arm2_gripper1">
      <inertial>
        <origin xyz="0 0 0" rpy="0 0 0"/>
        <mass value="0.2"/>
        <inertia ixx="0.0001"  ixy="0"  ixz="0" iyy="0.0001" iyz="0" izz="0.0001" />
      </inertial>
        <visual>
            <origin xyz="0 0.01 0" rpy="0 0 0" />
            <geometry>
                <box size="0.03 0.01 0.07"/>
            </geometry>
                <material name="material_green">
                    <color rgba="0.1 0.6 0.1 1"/>
                </material>
        </visual>
        <collision>
            <origin xyz="0 0.01 0" rpy="0 0 0" />
            <geometry>
                <box size="0.03 0.01 0.07"/>
            </geometry>
        </collision>
    </link>

    <link name="arm2_gripper2">
      <inertial>
        <origin xyz="0 0 0" rpy="0 0 0"/>
        <mass value="0.2"/>
        <inertia ixx="0.0001"  ixy="0"  ixz="0" iyy="0.0001" iyz="0" izz="0.0001" />
      </inertial>
        <visual>
            <origin xyz="0 0.01 0" rpy="0 0 0" />
            <geometry>
                <box size="0.03 0.01 0.07"/>
            </geometry>
                <material name="material_green">
                    <color rgba="0.1 0.6 0.1 1"/>
                </material>
        </visual>

        <collision>
            <origin xyz="0 0.01 0" rpy="0 0 0" />
            <geometry>
                <box size="0.03 0.01 0.07"/>
            </geometry>
        </collision>
    </link>


    <!-- JOINTS -->

    <joint name="jpx" type="prismatic">
        <parent link="ground" />
        <child link="virtual1" />
        <origin xyz="0 0 0" rpy="0 0 0"/>
        <axis xyz="1 0 0" />
        <limit lower="-2.967" upper="2.967" effort="176" velocity="1.7104" />
    </joint>

    <joint name="jpy" type="prismatic">
        <parent link="virtual1" />
        <child link="virtual2" />
        <origin xyz="0 0 0" rpy="0 0 0"/>
        <axis xyz="0 1 0" />
        <limit lower="-2.967" upper="2.967" effort="176" velocity="1.7104" />
    </joint>

    <joint name="jr" type="revolute">
        <parent link="virtual2" />
        <child link="base_link" />
        <origin xyz="0 -0.0 0.35" rpy="0 0 0"/>
        <axis xyz="0 0 1" />
        <limit lower="-2.967" upper="2.967" effort="176" velocity="1.7104" />
    </joint>


    <!-- JOINTS ARM 1 -->

    <joint name="j0" type="revolute">
        <parent link="base_link" />
        <child link="link1" />
        <!--<origin xyz="0 0 0.15" rpy="0 0 0"/>-->
        <origin xyz="-0.23 -0.2 0.375" rpy="0 -1.047197 0"/>
        <axis xyz="0 0 1" />
        <limit lower="-2.967" upper="2.967" effort="176" velocity="1.7104" />
        <calibration falling="90.0"/>
    </joint>
    <joint name="j1" type="revolute">
        <parent link="link1" />
        <child link="link2" />
        <origin xyz="0.000000 0.000000 0.19" rpy="0.000000 0.000000 0.000000" />
        <axis xyz="0 1 0" />
        <limit lower="-2.0944" upper="2.0944" effort="176" velocity="1.7104" />
        <calibration falling="-60.0"/>
    </joint>
    <joint name="j2" type="revolute">
        <parent link="link2" />
        <child link="link3" />
        <origin xyz="0.000000 0.000000 0.21" rpy="0.000000 0.000000 0.000000" />
        <axis xyz="0 0 1" />
        <limit lower="-2.967" upper="2.967" effort="110" velocity="1.7453" />
    </joint>
    <joint name="j3" type="revolute">
        <parent link="link3" />
        <child link="link4" />
        <origin xyz="0.000000 0.000000 0.19" rpy="0.000000 0.000000 3.1415926535897" />
        <axis xyz="0 1 0" />
        <limit lower="-2.0944" upper="2.0944" effort="110" velocity="2.2689" />
        <calibration falling="60.0"/>
    </joint>
    <joint name="j4" type="revolute">
        <parent link="link4" />
        <child link="link5" />
        <origin xyz="0.000000 0.000000 0.21" rpy="0.000000 0.000000 -3.1415926535897" />
        <axis xyz="0 0 1" />
        <limit lower="-2.967" upper="2.967" effort="110" velocity="2.4434" />
    </joint>
    <joint name="j5" type="revolute">
        <parent link="link5" />
        <child link="link6" />
        <origin xyz="0.000000 -0.06070 0.19" rpy="0.000000 0.000000 0.000000" />
        <axis xyz="0 1 0" />
        <limit lower="-2.0944" upper="2.0944" effort="40" velocity="3.1416" />
        <calibration falling="-30.0"/>
    </joint>
    <joint name="j6" type="revolute">
        <parent link="link6" />
        <child link="link7" />
        <origin xyz="0.000000 0.06070 0.081000" rpy="0.000000 0.000000 0.000000" />
        <axis xyz="0 0 1" />
        <limit lower="-3.0543" upper="3.0543" effort="40" velocity="3.1416" />
    </joint>

    <joint name="jgripper1" type="prismatic">
        <parent link="link7" />
        <child link="gripper1" />
        <origin xyz="0 0 0.07" rpy="0.000000 0.000000 0.000000" />
        <axis xyz="0 1 0" />
        <limit lower="-3.0543" upper="3.0543" effort="40" velocity="3.1416" />
    </joint>

    <joint name="jgripper2" type="prismatic">
        <parent link="link7" />
        <child link="gripper2" />
        <origin xyz="0 0 0.07" rpy="0.000000 0.000000 3.1415926535897" />
        <axis xyz="0 1 0" />
        <limit lower="-3.0543" upper="3.0543" effort="40" velocity="3.1416" />
    </joint>

    <!-- JOINTS ARM 2 -->

    <joint name="arm2_j0" type="revolute">
        <parent link="base_link" />
        <child link="arm2_link1" />
        <!--<origin xyz="0 0 0.15" rpy="0 0 0"/>-->
        <origin xyz="0.23 -0.2 0.375" rpy="0 -1.047197 3.141592"/>
        <axis xyz="0 0 1" />
        <limit lower="-2.967" upper="2.967" effort="176" velocity="1.7104" />
        <calibration falling="90.0"/>
    </joint>
    <joint name="arm2_j1" type="revolute">
        <parent link="arm2_link1" />
        <child link="arm2_link2" />
        <origin xyz="0.000000 0.000000 0.19" rpy="0.000000 0.000000 0.000000" />
        <axis xyz="0 1 0" />
        <limit lower="-2.0944" upper="2.0944" effort="176" velocity="1.7104" />
        <calibration falling="60.0"/>
    </joint>
    <joint name="arm2_j2" type="revolute">
        <parent link="arm2_link2" />
        <child link="arm2_link3" />
        <origin xyz="0.000000 0.000000 0.21" rpy="0.000000 0.000000 0.000000" />
        <axis xyz="0 0 1" />
        <limit lower="-2.967" upper="2.967" effort="110" velocity="1.7453" />
    </joint>
    <joint name="arm2_j3" type="revolute">
        <parent link="arm2_link3" />
        <child link="arm2_link4" />
        <origin xyz="0.000000 0.000000 0.19" rpy="0.000000 0.000000 3.1415926535897" />
        <axis xyz="0 1 0" />
        <limit lower="-2.0944" upper="2.0944" effort="110" velocity="2.2689" />
        <calibration falling="-60.0"/>
    </joint>
    <joint name="arm2_j4" type="revolute">
        <parent link="arm2_link4" />
        <child link="arm2_link5" />
        <origin xyz="0.000000 0.000000 0.21" rpy="0.000000 0.000000 -3.1415926535897" />
        <axis xyz="0 0 1" />
        <limit lower="-2.967" upper="2.967" effort="110" velocity="2.4434" />
    </joint>
    <joint name="arm2_j5" type="revolute">
        <parent link="arm2_link5" />
        <child link="arm2_link6" />
        <origin xyz="0.000000 -0.06070 0.19" rpy="0.000000 0.000000 0.000000" />
        <axis xyz="0 1 0" />
        <limit lower="-2.0944" upper="2.0944" effort="40" velocity="3.1416" />
        <calibration falling="30.0"/>
    </joint>
    <joint name="arm2_j6" type="revolute">
        <parent link="arm2_link6" />
        <child link="arm2_link7" />
        <origin xyz="0.000000 0.06070 0.081000" rpy="0.000000 0.000000 0.000000" />
        <axis xyz="0 0 1" />
        <limit lower="-3.0543" upper="3.0543" effort="40" velocity="3.1416" />
    </joint>

    <joint name="arm2_jgripper1" type="prismatic">
        <parent link="arm2_link7" />
        <child link="arm2_gripper1" />
        <origin xyz="0 0 0.07" rpy="0.000000 0.000000 0.000000" />
        <axis xyz="0 1 0" />
        <limit lower="-3.0543" upper="3.0543" effort="40" velocity="3.1416" />
    </joint>

    <joint name="arm2_jgripper2" type="prismatic">
        <parent link="arm2_link7" />
        <child link="arm2_gripper2" />
        <origin xyz="0 0 0.07" rpy="0.000000 0.000000 3.1415926535897" />
        <axis xyz="0 1 0" />
        <limit lower="-3.0543" upper="3.0543" effort="40" velocity="3.1416" />
    </joint>
</robot>