<?xml version="1.0" ?>
<!--Autogenerated by "taco/models/sdf2urdf" converter from "../kuka_iiwa/kuka_iiwa.sdf"-->
<robot name="robotObject">

    <link name="ground">
        <inertial>
            <origin xyz="0 0 0" rpy="0 0 0"/>
            <mass value="0.0001"/>
            <inertia ixx="0.000001"  ixy="0"  ixz="0" iyy="0.000001" iyz="0.0" izz="0.000001" />
        </inertial>
    </link>

    <link name="virtual1">
        <inertial>
            <origin xyz="0 0 0" rpy="0 0 0"/>
            <mass value="0.0001"/>
            <inertia ixx="0.000001"  ixy="0"  ixz="0" iyy="0.000001" iyz="0.0" izz="0.000001" />
        </inertial>
    </link>

    <link name="virtual2">
        <inertial>
            <origin xyz="0 0 0" rpy="0 0 0"/>
            <mass value="0.0001"/>
            <inertia ixx="0.000001"  ixy="0"  ixz="0" iyy="0.000001" iyz="0.0" izz="0.000001" />
        </inertial>
    </link>

    <link name="virtual3">
        <inertial>
            <origin xyz="0 0 0" rpy="0 0 0"/>
            <mass value="0.0001"/>
            <inertia ixx="0.000001"  ixy="0"  ixz="0" iyy="0.000001" iyz="0.0" izz="0.000001" />
        </inertial>
    </link>

    <link name="base_link">
        <inertial>
            <origin xyz="0 -1.0 0.5" rpy="0 0 0"/>
            <mass value="5"/>
            <inertia ixx="0.05"  ixy="0"  ixz="0" iyy="0.06" iyz="0" izz="0.03" />
        </inertial>
    <visual>
        <origin xyz="0 -1.0 0.1" rpy="0 -0 0" />
        <geometry>
            <box size="0.1 0.1 0.1"/>
        </geometry>
        <material name="material_green">
            <color rgba="0.1 0.3 0.8 1"/>
        </material>
    </visual>
        <!-- <collision>
            <origin xyz="0 0 0" rpy="0 -0 0" />
            <geometry>
                <mesh filename="../../../robot_models/iiwa7/meshes/base.obj" scale="1 1 1" />
            </geometry>
        </collision> -->
    </link>




    <joint name="jpx" type="prismatic">
        <parent link="ground" />
        <child link="virtual1" />
        <origin xyz="0 0 0" rpy="0 0 0"/>
        <axis xyz="1 0 0" />
        <limit lower="-2.967" upper="2.967" effort="176" velocity="1.7104" />
    </joint>

    <joint name="jpy" type="prismatic">
        <parent link="virtual1" />
        <child link="virtual2" />
        <origin xyz="0 0 0" rpy="0 0 0"/>
        <axis xyz="0 1 0" />
        <limit lower="-2.967" upper="2.967" effort="176" velocity="1.7104" />
    </joint>

    <joint name="jpz" type="prismatic">
        <parent link="virtual2" />
        <child link="virtual3" />
        <origin xyz="0 0 0" rpy="0 0 0"/>
        <axis xyz="0 0 1" />
        <limit lower="-2.967" upper="2.967" effort="176" velocity="1.7104" />
    </joint>

    <joint name="jr" type="revolute">
        <parent link="virtual3" />
        <child link="base_link" />
        <origin xyz="0 0 0.35" rpy="0 0 0"/>
        <axis xyz="0 0 1" />
        <limit lower="-2.967" upper="2.967" effort="176" velocity="1.7104" />
    </joint>

</robot>